<?xml version="1.0" encoding="UTF-8"?>
<!-- Generated by org.testng.reporters.JUnitReportReporter -->
<testsuite hostname="PSDLAP385" failures="2" tests="14" name="test.BlogsAndInsightsTest" time="224.835" errors="0" timestamp="2024-12-20T16:56:49 IST" skipped="4">
  <testcase classname="test.BlogsAndInsightsTest" name="Validate_BlogsAndInsights_Button_Click_TC_001" time="11.983"/>
  <system-out/>
  <testcase classname="test.BlogsAndInsightsTest" name="Validate_ReadMoreAboutUs_Button_Click_TC_002" time="15.207">
    <failure message="expected [About Us - Pursuit Software] but found [Blogs &amp; Insights - Pursuit Software]" type="java.lang.AssertionError">
      <![CDATA[java.lang.AssertionError: expected [About Us - Pursuit Software] but found [Blogs & Insights - Pursuit Software]
at org.testng.Assert.fail(Assert.java:99)
at org.testng.Assert.failNotEquals(Assert.java:1037)
at org.testng.Assert.assertEqualsImpl(Assert.java:140)
at org.testng.Assert.assertEquals(Assert.java:122)
at org.testng.Assert.assertEquals(Assert.java:629)
at org.testng.Assert.assertEquals(Assert.java:639)
at test.BlogsAndInsightsTest.Validate_ReadMoreAboutUs_Button_Click_TC_002(BlogsAndInsightsTest.java:31)
at java.base/jdk.internal.reflect.DirectMethodHandleAccessor.invoke(DirectMethodHandleAccessor.java:103)
at java.base/java.lang.reflect.Method.invoke(Method.java:580)
at org.testng.internal.MethodInvocationHelper.invokeMethod(MethodInvocationHelper.java:133)
at org.testng.internal.TestInvoker.invokeMethod(TestInvoker.java:598)
at org.testng.internal.TestInvoker.retryFailed(TestInvoker.java:213)
at org.testng.internal.MethodRunner.runInSequence(MethodRunner.java:58)
at org.testng.internal.TestInvoker$MethodInvocationAgent.invoke(TestInvoker.java:824)
at org.testng.internal.TestInvoker.invokeTestMethods(TestInvoker.java:146)
at org.testng.internal.TestMethodWorker.invokeTestMethods(TestMethodWorker.java:146)
at org.testng.internal.TestMethodWorker.run(TestMethodWorker.java:128)
at java.base/java.util.ArrayList.forEach(ArrayList.java:1597)
at org.testng.TestRunner.privateRun(TestRunner.java:794)
at org.testng.TestRunner.run(TestRunner.java:596)
at org.testng.SuiteRunner.runTest(SuiteRunner.java:377)
at org.testng.SuiteRunner.runSequentially(SuiteRunner.java:371)
at org.testng.SuiteRunner.privateRun(SuiteRunner.java:332)
at org.testng.SuiteRunner.run(SuiteRunner.java:276)
at org.testng.SuiteRunnerWorker.runSuite(SuiteRunnerWorker.java:53)
at org.testng.SuiteRunnerWorker.run(SuiteRunnerWorker.java:96)
at org.testng.TestNG.runSuitesSequentially(TestNG.java:1212)
at org.testng.TestNG.runSuitesLocally(TestNG.java:1134)
at org.testng.TestNG.runSuites(TestNG.java:1063)
at org.testng.TestNG.run(TestNG.java:1031)
at org.testng.remote.AbstractRemoteTestNG.run(AbstractRemoteTestNG.java:115)
at org.testng.remote.RemoteTestNG.initAndRun(RemoteTestNG.java:293)
at org.testng.remote.RemoteTestNG.main(RemoteTestNG.java:91)
]]>
    </failure>
  </testcase> <!-- Validate_ReadMoreAboutUs_Button_Click_TC_002 -->
  <system-out/>
  <testcase classname="test.BlogsAndInsightsTest" name="Validate_ReadMoreAboutUs_Button_Click_TC_002" time="14.263">
    <skipped/>
  </testcase> <!-- Validate_ReadMoreAboutUs_Button_Click_TC_002 -->
  <system-out/>
  <testcase classname="test.BlogsAndInsightsTest" name="Validate_ReadMoreAboutUs_Button_Click_TC_002" time="15.625">
    <skipped/>
  </testcase> <!-- Validate_ReadMoreAboutUs_Button_Click_TC_002 -->
  <system-out/>
  <testcase classname="test.BlogsAndInsightsTest" name="Validate_ContactUs_Button_Click_TC_003" time="15.509">
    <skipped/>
  </testcase> <!-- Validate_ContactUs_Button_Click_TC_003 -->
  <system-out/>
  <testcase classname="test.BlogsAndInsightsTest" name="Validate_ContactUs_Button_Click_TC_003" time="14.907">
    <skipped/>
  </testcase> <!-- Validate_ContactUs_Button_Click_TC_003 -->
  <system-out/>
  <testcase classname="test.BlogsAndInsightsTest" name="Validate_ContactUs_Button_Click_TC_003" time="14.648">
    <failure message="expected [Contact Us - Pursuit Software] but found [Blogs &amp; Insights - Pursuit Software]" type="java.lang.AssertionError">
      <![CDATA[java.lang.AssertionError: expected [Contact Us - Pursuit Software] but found [Blogs & Insights - Pursuit Software]
at org.testng.Assert.fail(Assert.java:99)
at org.testng.Assert.failNotEquals(Assert.java:1037)
at org.testng.Assert.assertEqualsImpl(Assert.java:140)
at org.testng.Assert.assertEquals(Assert.java:122)
at org.testng.Assert.assertEquals(Assert.java:629)
at org.testng.Assert.assertEquals(Assert.java:639)
at test.BlogsAndInsightsTest.Validate_ContactUs_Button_Click_TC_003(BlogsAndInsightsTest.java:39)
at java.base/jdk.internal.reflect.DirectMethodHandleAccessor.invoke(DirectMethodHandleAccessor.java:103)
at java.base/java.lang.reflect.Method.invoke(Method.java:580)
at org.testng.internal.MethodInvocationHelper.invokeMethod(MethodInvocationHelper.java:133)
at org.testng.internal.TestInvoker.invokeMethod(TestInvoker.java:598)
at org.testng.internal.TestInvoker.retryFailed(TestInvoker.java:213)
at org.testng.internal.MethodRunner.runInSequence(MethodRunner.java:58)
at org.testng.internal.TestInvoker$MethodInvocationAgent.invoke(TestInvoker.java:824)
at org.testng.internal.TestInvoker.invokeTestMethods(TestInvoker.java:146)
at org.testng.internal.TestMethodWorker.invokeTestMethods(TestMethodWorker.java:146)
at org.testng.internal.TestMethodWorker.run(TestMethodWorker.java:128)
at java.base/java.util.ArrayList.forEach(ArrayList.java:1597)
at org.testng.TestRunner.privateRun(TestRunner.java:794)
at org.testng.TestRunner.run(TestRunner.java:596)
at org.testng.SuiteRunner.runTest(SuiteRunner.java:377)
at org.testng.SuiteRunner.runSequentially(SuiteRunner.java:371)
at org.testng.SuiteRunner.privateRun(SuiteRunner.java:332)
at org.testng.SuiteRunner.run(SuiteRunner.java:276)
at org.testng.SuiteRunnerWorker.runSuite(SuiteRunnerWorker.java:53)
at org.testng.SuiteRunnerWorker.run(SuiteRunnerWorker.java:96)
at org.testng.TestNG.runSuitesSequentially(TestNG.java:1212)
at org.testng.TestNG.runSuitesLocally(TestNG.java:1134)
at org.testng.TestNG.runSuites(TestNG.java:1063)
at org.testng.TestNG.run(TestNG.java:1031)
at org.testng.remote.AbstractRemoteTestNG.run(AbstractRemoteTestNG.java:115)
at org.testng.remote.RemoteTestNG.initAndRun(RemoteTestNG.java:293)
at org.testng.remote.RemoteTestNG.main(RemoteTestNG.java:91)
]]>
    </failure>
  </testcase> <!-- Validate_ContactUs_Button_Click_TC_003 -->
  <system-out/>
  <testcase classname="test.BlogsAndInsightsTest" name="Validate_Page_2_Button_Click_TC_004" time="15.228"/>
  <system-out/>
  <testcase classname="test.BlogsAndInsightsTest" name="Validate_Blog_1_Button_Click_TC_005" time="16.337"/>
  <system-out/>
  <testcase classname="test.BlogsAndInsightsTest" name="Validate_Blog_2_Button_Click_TC_006" time="16.251"/>
  <system-out/>
  <testcase classname="test.BlogsAndInsightsTest" name="Validate_Blog_3_Button_Click_TC_007" time="16.795"/>
  <system-out/>
  <testcase classname="test.BlogsAndInsightsTest" name="Validate_Blog_4_Button_Click_TC_008" time="19.106"/>
  <system-out/>
  <testcase classname="test.BlogsAndInsightsTest" name="Validate_Blog_4_Button_Click_TC_009" time="19.841"/>
  <system-out/>
  <testcase classname="test.BlogsAndInsightsTest" name="Validate_Blog_4_Button_Click_TC_010" time="19.135"/>
  <system-out/>
</testsuite> <!-- test.BlogsAndInsightsTest -->
